Workbook

Sheet Судовой состав МСС
A1: № п/п | B1: Тип | C1: Район | D1: Наименование судна | E1: Проект | F1: Год постройки | G1: Тип судна | H1: Класс | I1: ИМО | J1: Порт регистрации | K1: Нотация | L1: GRT | M1: кВт | N1: BP | O1: Район плавания | P1: Возраст судна | Q1: Длина | R1: Ширина | S1: Филиал
A2: 168 | B2: катер | D2: Camper 470 | E2: CAMPER RIB Atlantic series 470 | G2: RIB | H2: ГИМС | J2: Корсаков | K2: Маломерное | O2: Прибрежное | Q2: 4.7 | R2: 1.7 | S2: Сахалинский
A3: 169 | B3: катер | D3: RM540 | E3: RM 540 LTB | F3: 2022 | G3: RIB | H3: ГИМС | J3: Санкт-Петербург | K3: Маломерное | M3: 44.1 | O3: Прибрежное | P3: 4 | Q3: 5.4 | R3: 2.23 | S3: Балтийский
A4: 170 | B4: катер | D4: YAXE (РАА 96-39) | E4: HD 365 | F4: 2008 | G4: Надувная лодка | H4: ГИМС | J4: Архангельск | K4: Маломерное | M4: 4.4 | O4: Прибрежное | P4: 18 | Q4: 3.65 | R4: 1.75 | S4: Балтийский
A5: 162 | B5: катер | D5: АДМИРАЛ ADM-610-1 | E5: Адмирал 610 | F5: 2018 | G5: Моторное судно | H5: ГИМС | J5: Мурманск | K5: Маломерное | L5: 1.975 | M5: 55.15 | O5: Прибрежное | P5: 8 | Q5: 6.1 | R5: 2.2 | S5: Северный
A6: 163 | B6: катер | D6: АДМИРАЛ ADM-610-2 | E6: Адмирал 610 | F6: 2018 | G6: Моторное судно | H6: ГИМС | J6: Мурманск | K6: Маломерное | L6: 1.975 | M6: 55.15 | O6: Прибрежное | P6: 5 | Q6: 6.1 | R6: 2.2 | S6: Северный
A7: 171 | B7: катер | D7: Адмирал-1 | F7: 2022 | G7: Спасательный катер, бонопостановщик | H7: РМРС | J7: Мурманск | K7: Маломерное | M7: 36.8 | O7: Прибрежное | P7: 4 | Q7: 5 | R7: 2.2 | S7: Северный
A8: 172 | B8: катер | D8: Адмирал-2 | F8: 2022 | G8: Спасательный катер, бонопостановщик | H8: РМРС | J8: Мурманск | K8: Маломерное | M8: 36.8 | O8: Прибрежное | P8: 4 | Q8: 5 | R8: 2.2 | S8: Северный
A9: 173 | B9: катер | D9: Адмирал-3 | F9: 2023 | G9: Поисково-спасательные и буксирные операции в целях защиты и сохранения морской среды | H9: РМРС | J9: Мурманск | K9: Маломерное | M9: 29.4 | O9: Прибрежное | P9: 3 | Q9: 5 | R9: 2.2 | S9: Северный
A10: 174 | B10: катер | D10: Адмирал-4 | F10: 2023 | G10: Поисково-спасательные и буксирные операции в целях защиты и сохранения морской среды | H10: РМРС | J10: Мурманск | K10: Маломерное | M10: 29.4 | O10: Прибрежное | P10: 3 | Q10: 5 | R10: 2.2 | S10: Северный
A11: 155 | B11: скб | C11: БЕР | D11: Айруп | E11: 17MJ | F11: 2017 | G11: Патрульное | H11: РМРС | J11: Корсаков | K11: KM* [1] HSC | L11: 27 | M11: 1472 | O11: R3-RSN | P11: 9 | Q11: 18.2 | R11: 3.8 | S11: Камчатский
A12: 176 | B12: катер | D12: Аквамаран-1 | E12: Аквамаран | F12: 2018 | G12: RIB | H12: РМРС | J12: Новороссийск | K12: Маломерное | M12: 22.1 | O12: Прибрежное | P12: 8 | Q12: 3.8 | R12: 1.75 | S12: Азово-Черноморский
A13: 175 | B13: катер | D13: Аквамаран-1 | E13: Аквамаран 470 | F13: 2017 | G13: Поисково-спасательные и буксирные операции в целях защиты и сохранения морской среды | H13: РМРС | J13: Мурманск | K13: Маломерное | M13: 29.4 | O13: Прибрежное | P13: 9 | Q13: 4.7 | R13: 2.1 | S13: Северный
A14: 178 | B14: катер | D14: Аквамаран-2 | E14: Аквамаран | F14: 2018 | G14: RIB | H14: РМРС | J14: Новороссийск | K14: Маломерное | M14: 22.1 | O14: Прибрежное | P14: 8 | Q14: 3.8 | R14: 1.75 | S14: Азово-Черноморский
A15: 177 | B15: катер | D15: Аквамаран-2 | E15: Аквамаран 470 | F15: 2017 | G15: Поисково-спасательные и буксирные операции в целях защиты и сохранения морской среды | H15: РМРС | J15: Мурманск | K15: Маломерное | M15: 29.4 | O15: Прибрежное | P15: 9 | Q15: 4.7 | R15: 2.1 | S15: Северный
A16: 179 | B16: катер | D16: Аквамаран-3 | E16: Altair PRO ultra 460 | F16: 2022 | G16: моторная лодка | H16: ГИМС | K16: Маломерное | M16: 29.4 | O16: Прибрежное | P16: 4 | Q16: 4.6 | R16: 2.02 | S16: Северный
A17: 180 | B17: катер | D17: Аквамаран-4 | E17: Altair PRO ultra 460 | F17: 2022 | G17: моторная лодка | H17: ГИМС | K17: Маломерное | M17: 29.4 | O17: Прибрежное | P17: 4 | Q17: 4.6 | R17: 2.02 | S17: Северный
A18: 121 | B18: скб | C18: АЧ | D18: Александр Сизонцев | E18: А40-2Б-ЯР | F18: 2016 | G18: Бонопостановщик | H18: РМРС | J18: Новороссийск | K18: KM* Ice2 R3-RSN AUT3 oil recovery ship(>60°C) | L18: 56 | M18: 1176 | O18: R3 | P18: 10 | Q18: 19.83 | R18: 5 | S18: Азово-Черноморский
A19: 181 | B19: скб | C19: БАЛ | D19: Алиот | E19: HS-1500 | F19: 1989 | G19: Спасательное, бонопостановщик | H19: РМРС | J19: Санкт-Петербург | K19: Маломерное | M19: 524 | O19: МП, ВВП | P19: 37 | Q19: 14.75 | R19: 4 | S19: Балтийский
A20: 182 | B20: ск | C20: БАЛ | D20: Альтаир | E20: МРК-1000 | F20: 2019 | G20: Бонопостановщик, мусоросбощик | H20: РМРС | J20: Санкт-Петербург | K20: Маломерное | M20: 398 | O20: Прибрежное | P20: 7 | Q20: 11.4 | R20: 3.9 | S20: Балтийский
A21: 183 | B21: скб | C21: БАЛ | D21: Альфард | E21: HS-1500 | F21: 1989 | G21: Бонопостановщик | H21: РМРС | J21: Санкт-Петербург | K21: Маломерное | M21: 524 | O21: Прибрежное | P21: 37 | Q21: 14.75 | R21: 4 | S21: Балтийский
A22: 78 | B22: сб | C22: ЯП | D22: Амбер | E22: 31M T.S. TUG | F22: 2007 | G22: Буксир | H22: РМРС (сейчас RINA) | I22: 9431939 | J22: Владивосток | K22: KM*Tug | L22: 286 | M22: 2388 | N22: 42 | O22: Неограниченный | P22: 19 | Q22: 31 | R22: 9 | S22: Приморский
A23: 184 | B23: катер | D23: Амур-2 | E23: Амур | F23: 1987 | G23: Моторная лодка | H23: ГИМС | J23: Астрахань | K23: Маломерное | M23: 51.5 | O23: Прибрежное | P23: 39 | Q23: 6.1 | R23: 1.84 | S23: Каспийский
A24: 185 | B24: катер | D24: Амур-В | E24: Амур | F24: 1987 | G24: Моторная лодка | H24: ГИМС | J24: Астрахань | K24: Маломерное | M24: 51.5 | O24: Прибрежное | P24: 39 | Q24: 6.3 | R24: 1.84 | S24: Каспийский
A25: 131 | B25: скб | C25: БАР | D25: Анатолий Веретехин | E25: А40-2Б | F25: 2010 | G25: Бонопостановщик | H25: РМРС | J25: Новороссийск | K25: KM* Ice2 R3 AUT3 oil recovery ship(>60°C) | L25: 46 | M25: 882 | O25: R3 | P25: 16 | Q25: 19.9 | R25: 4.7 | S25: Северный
A26: 132 | B26: скб | C26: АЧ | D26: Анатолий Ткачев | E26: А40-2Б | F26: 2010 | G26: Бонопостановщик | H26: РМРС | J26: Новороссийск | K26: KM* Ice2 R3-RSN AUT3 oil recovery ship(>60°C) | L26: 46 | M26: 882 | O26: R3 | P26: 16 | Q26: 19.9 | R26: 4.7 | S26: Азово-Черноморский
A27: 186 | B27: сквп | C27: КАСП | D27: Арго | E27: 110 | F27: 2005 | G27: Катер | H27: РМРС | J27: Астрахань | K27: Маломерное | M27: 117.68 | O27: Прибрежное | P27: 21 | Q27: 8.74 | R27: 3.8 | S27: Каспийский
A28: 188 | B28: скб | C28: БАЛ | D28: Арнеб | E28: HS1500 | F28: 1989 | G28: Бонопостановщик | H28: РМРС | J28: Санкт-Петербург | K28: Маломерное | M28: 524 | O28: Прибрежное | P28: 37 | Q28: 14.75 | R28: 4 | S28: Балтийский
A29: 1 | B29: мфасс | C29: БАЛ | D29: Артемис Оффшор | E29: YX3205 | F29: 2018 | G29: Судно специального назначения | H29: РКО (Конв) | I29: 9747194 | J29: Владивосток | K29: IСЕ1 (НULL;МАСНINЕRY) АUТ1 FF1WS DYNРОS-2 ВWМ (Е-S) НЕLIDЕСК RР-2 DG IWS SРЕСIАL РURРОSЕ SНIР/SUРРLY VЕSSЕL(ОS) | L29: 4930 | M29: 4420 | O29: Неограниченный | P29: 8 | Q29: 77.94 | R29: 22 | S29: Приморский
A30: 187 | B30: ск | C30: КАСП | D30: Артик | E30: Artic-1200 | F30: 2018 | G30: RIB | H30: РМРС | J30: Астрахань | K30: Маломерное | M30: 397 | O30: Прибрежное | P30: 8 | Q30: 11.7 | R30: 4.1 | S30: Каспийский
A31: 138 | B31: сб | C31: БАЛ | D31: АСПТР-5 | E31: Р-100 | F31: 1967 | G31: морской буксир прибрежного плавания | H31: РМРС | J31: Архангельск | K31: Маломерное | L31: 45 | M31: 220 | O31: Прибрежное | P31: 59 | Q31: 19.1 | R31: 6 | S31: Балтийский
A32: 189 | B32: баржа | D32: АСПТР-7 | E32: 02280 | F32: 1981 | G32: несамоходный плашкоут | H32: РКО | J32: Архангельск | K32: Маломерное | O32: Прибрежное | P32: 45 | Q32: 17.92 | R32: 3.96 | S32: Балтийский
A33: 146 | B33: сб | C33: БАЛ | D33: Б-104 | E33: 1439 | F33: 1985 | G33: Буксирный теплоход | H33: РКО | J33: Санкт-Петербург | K33: О мс2,0 | L33: 35.3 | M33: 110 | O33: О | P33: 41 | Q33: 17.37 | R33: 4 | S33: Балтийский
A34: 88 | B34: сб | C34: БАЛ | D34: Б-1214 | E34: Р33Б | F34: 1985 | G34: Буксирный теплоход | H34: РКО | J34: Санкт-Петербург | K34: О2,0 (лед10) | L34: 217 | M34: 450 | O34: О | P34: 41 | Q34: 34.35 | R34: 8 | S34: Балтийский
A35: 153 | B35: сб | C35: БАЛ | D35: Б-123 | E35: 1437 | F35: 1975 | G35: Буксирный теплоход | H35: РКО | J35: Санкт-Петербург | K35: О мс2,0 (лед15) | L35: 31 | M35: 165 | O35: О | P35: 51 | Q35: 13.6 | R35: 4.17 | S35: Балтийский
A36: 147 | B36: сб | C36: АЧ | D36: Б-245 | E36: 1439 | F36: 1984 | G36: Буксир | H36: РКО | J36: Ростов-на-Дону | K36: О мс2,0 | L36: 35 | M36: 110 | O36: О | P36: 42 | Q36: 17.37 | R36: 3.8 | S36: Азово-Черноморский
A37: 190 | B37: сб | D37: Б-407 | E37: БМК-130М | F37: 1988 | G37: Буксирно-моторный катер | H37: РКО | J37: Москва | K37: Р мс 1,2 | M37: 73.5 | O37: Р | P37: 38 | Q37: 7.85 | R37: 2.1 | S37: Тверской
A38: 95 | B38: сб | D38: Б-505 | E38: 911В | F38: 1972 | G38: Буксир-толкач | H38: РКО | J38: Москва | K38: Р1,2А | L38: 153 | M38: 220 | O38: Р | P38: 54 | Q38: 27.4 | R38: 6.6 | S38: Тверской
A39: 96 | B39: сб | C39: АЧ | D39: Б-507 | E39: Р-103А | F39: 1981 | G39: Буксир | H39: РКО | J39: Ростов-на-Дону | K39: О2,0(ЛЕД20) | L39: 135.6 | M39: 220 | O39: О | P39: 45 | Q39: 20 | R39: 6.6 | S39: Азово-Черноморский
A40: 91 | B40: сб | D40: Б-508 | E40: Р 14 | F40: 1971 | G40: Буксир-толкач | H40: РКО | J40: Москва | K40: Р1,2 (лед20) | L40: 162 | M40: 332 | O40: Р | P40: 55 | Q40: 28.4 | R40: 6.6 | S40: Тверской
...

Sheet Лист1
A1: Район | B1: ВСЕГО | D1: Многофункциональное аварийно-спасательное судно | G1: Спасательные буксирные и нефтесборные суда | L1: Спасательный катер-бонопостановщик или катер-бонопостановщик/ нефтесборщик
D2: Стандарт | E2: Факт | F2: Откл. | G2: Стандарт | H2: ТБС+ АСС | I2: НСС | J2: Всего | K2: Откл. | L2: Стандарт | M2: Факт | N2: Откл.
A3: Западный район Арктического бассейна | B3: =E3+J3+M3 -> #REF! | D3: 12 | E3: =COUNTIFS('Судовой состав МСС'!C2:C274,"БАР",'Судовой состав МСС'!#REF!,"мфасс") -> #REF! | F3: =E3-D3 -> #REF! | G3: 10 | H3: =COUNTIFS('Судовой состав МСС'!C$2:C$274,"БАР",'Судовой состав МСС'!#REF!,"сб") -> #REF! | I3: =COUNTIFS('Судовой состав МСС'!C2:C274,"БАР",'Судовой состав МСС'!#REF!,"нсс") -> #REF! | J3: =H3+I3 -> #REF! | K3: =J3-G3 -> #REF! | L3: 10 | M3: =COUNTIFS('Судовой состав МСС'!C2:C274,"БАР",'Судовой состав МСС'!#REF!,"скб") -> #REF! | N3: =M3-L3 -> #REF!
A4: Восточный район Арктического бассейна | B4: =E4+J4+M4 -> #REF! | D4: 6 | E4: =COUNTIFS('Судовой состав МСС'!C2:C274,"ЧУК",'Судовой состав МСС'!#REF!,"мфасс") -> #REF! | F4: =E4-D4 -> #REF! | G4: 8 | H4: =COUNTIFS('Судовой состав МСС'!C2:C274,"ЧУК",'Судовой состав МСС'!#REF!,"сб") -> #REF! | I4: =COUNTIFS('Судовой состав МСС'!C2:C274,"ЧУК",'Судовой состав МСС'!#REF!,"нсс") -> #REF! | J4: =H4+I4 -> #REF! | K4: =J4-G4 -> #REF! | L4: 8 | M4: =COUNTIFS('Судовой состав МСС'!C2:C274,"ЧУК",'Судовой состав МСС'!#REF!,"скб") -> #REF! | N4: =M4-L4 -> #REF!
A5: Берингово море | B5: =E5+J5+M5 -> #REF! | D5: 3 | E5: =COUNTIFS('Судовой состав МСС'!C2:C274,"БЕР",'Судовой состав МСС'!#REF!,"мфасс") -> #REF! | F5: =E5-D5 -> #REF! | G5: 8 | H5: =COUNTIFS('Судовой состав МСС'!C2:C274,"БЕР",'Судовой состав МСС'!#REF!,"сб") -> #REF! | I5: =COUNTIFS('Судовой состав МСС'!C2:C274,"БЕР",'Судовой состав МСС'!#REF!,"нсс") -> #REF! | J5: =H5+I5 -> #REF! | K5: =J5-G5 -> #REF! | L5: 8 | M5: =COUNTIFS('Судовой состав МСС'!C2:C274,"БЕР",'Судовой состав МСС'!#REF!,"скб") -> #REF! | N5: =M5-L5 -> #REF!
A6: Охотское море и Тататрский пролив | B6: =E6+J6+M6 -> #REF! | D6: 9 | E6: =COUNTIFS('Судовой состав МСС'!C2:C274,"ОМ",'Судовой состав МСС'!#REF!,"мфасс") -> #REF! | F6: =E6-D6 -> #REF! | G6: 6 | H6: =COUNTIFS('Судовой состав МСС'!C2:C274,"ОМ",'Судовой состав МСС'!#REF!,"сб") -> #REF! | I6: =COUNTIFS('Судовой состав МСС'!C2:C274,"ОМ",'Судовой состав МСС'!#REF!,"нсс") -> #REF! | J6: =H6+I6 -> #REF! | K6: =J6-G6 -> #REF! | L6: 7 | M6: =COUNTIFS('Судовой состав МСС'!C2:C274,"ОМ",'Судовой состав МСС'!#REF!,"скб") -> #REF! | N6: =M6-L6 -> #REF!
A7: Японское море | B7: =E7+J7+M7 -> #REF! | D7: 3 | E7: =COUNTIFS('Судовой состав МСС'!C2:C274,"ЯП",'Судовой состав МСС'!#REF!,"мфасс") -> #REF! | F7: =E7-D7 -> #REF! | G7: 8 | H7: =COUNTIFS('Судовой состав МСС'!C2:C274,"ЯП",'Судовой состав МСС'!#REF!,"сб") -> #REF! | I7: =COUNTIFS('Судовой состав МСС'!C2:C274,"ЯП",'Судовой состав МСС'!#REF!,"нсс") -> #REF! | J7: =H7+I7 -> #REF! | K7: =J7-G7 -> #REF! | L7: 8 | M7: =COUNTIFS('Судовой состав МСС'!C2:C274,"ЯП",'Судовой состав МСС'!#REF!,"скб") -> #REF! | N7: =M7-L7 -> #REF!
A8: Каспийское море | B8: =E8+J8+M8 -> #REF! | D8: 0 | E8: =COUNTIFS('Судовой состав МСС'!C2:C274,"КАСП",'Судовой состав МСС'!#REF!,"мфасс") -> #REF! | F8: =E8-D8 -> #REF! | G8: 4 | H8: =COUNTIFS('Судовой состав МСС'!C2:C274,"КАСП",'Судовой состав МСС'!#REF!,"сб") -> #REF! | I8: =COUNTIFS('Судовой состав МСС'!C2:C274,"КАСП",'Судовой состав МСС'!#REF!,"нсс") -> #REF! | J8: =H8+I8 -> #REF! | K8: =J8-G8 -> #REF! | L8: 4 | M8: =COUNTIFS('Судовой состав МСС'!C2:C274,"КАСП",'Судовой состав МСС'!#REF!,"скб") -> #REF! | N8: =M8-L8 -> #REF!
A9: Черноморско-Азовский бассейн | B9: =E9+J9+M9 -> #REF! | D9: 12 | E9: =COUNTIFS('Судовой состав МСС'!C2:C274,"АЧ",'Судовой состав МСС'!#REF!,"мфасс") -> #REF! | F9: =E9-D9 -> #REF! | G9: 12 | H9: =COUNTIFS('Судовой состав МСС'!C2:C274,"АЧ",'Судовой состав МСС'!#REF!,"сб") -> #REF! | I9: =COUNTIFS('Судовой состав МСС'!C2:C274,"АЧ",'Судовой состав МСС'!#REF!,"нсс") -> #REF! | J9: =H9+I9 -> #REF! | K9: =J9-G9 -> #REF! | L9: 12 | M9: =COUNTIFS('Судовой состав МСС'!C2:C274,"АЧ",'Судовой состав МСС'!#REF!,"скб") -> #REF! | N9: =M9-L9 -> #REF!
A10: Балтийское море | B10: =E10+J10+M10 -> #REF! | D10: 6 | E10: =COUNTIFS('Судовой состав МСС'!C2:C274,"БАЛ",'Судовой состав МСС'!#REF!,"мфасс") -> #REF! | F10: =E10-D10 -> #REF! | G10: 10 | H10: =COUNTIFS('Судовой состав МСС'!C2:C274,"БАЛ",'Судовой состав МСС'!#REF!,"сб") -> #REF! | I10: =COUNTIFS('Судовой состав МСС'!C2:C274,"БАЛ",'Судовой состав МСС'!#REF!,"нсс") -> #REF! | J10: =H10+I10 -> #REF! | K10: =J10-G10 -> #REF! | L10: 10 | M10: =COUNTIFS('Судовой состав МСС'!C2:C274,"БАЛ",'Судовой состав МСС'!#REF!,"скб") -> #REF! | N10: =M10-L10 -> #REF!
A11: ИТОГО | B11: =SUM(B3:B10) -> #REF! | D11: =SUM(D3:D10) -> 51 | E11: =SUM(E3:E10) -> #REF! | F11: =SUM(F3:F10) -> #REF! | G11: =SUM(G3:G10) -> 66 | H11: =SUM(H3:H10) -> #REF! | I11: =SUM(I3:I10) -> #REF! | J11: =SUM(J3:J10) -> #REF! | K11: =SUM(K3:K10) -> #REF! | ... N11: =SUM(N3:N10) -> #REF!
A12: Средний возраст | E12: 12.6 | H12: 30 | I12: 21.3 | J12: 28.7 | M12: 15.4
